Watching for file changes with StatReloader
Not Found: /api/register/
Not Found: /api/tradeitems/
Not Found: /api/tradeitems/
Not Found: /api/wishlist/add/1/
Not Found: /api/userprofiles/
Not Found: /api/tradeitems/
Internal Server Error: /api/reviews/2/
Traceback (most recent call last):
  File "C:\Python\animedia_api\.venv\Lib\site-packages\django\core\handlers\exception.py", line 55, in inner
    response = get_response(request)
  File "C:\Python\animedia_api\.venv\Lib\site-packages\django\core\handlers\base.py", line 197, in _get_response
    response = wrapped_callback(request, *callback_args, **callback_kwargs)
  File "C:\Python\animedia_api\.venv\Lib\site-packages\django\views\decorators\csrf.py", line 65, in _view_wrapper
    return view_func(request, *args, **kwargs)
  File "C:\Python\animedia_api\.venv\Lib\site-packages\rest_framework\viewsets.py", line 125, in view
    return self.dispatch(request, *args, **kwargs)
           ~~~~~~~~~~~~~^^^^^^^^^^^^^^^^^^^^^^^^^^
  File "C:\Python\animedia_api\.venv\Lib\site-packages\rest_framework\views.py", line 515, in dispatch
    response = self.handle_exception(exc)
  File "C:\Python\animedia_api\.venv\Lib\site-packages\rest_framework\views.py", line 475, in handle_exception
    self.raise_uncaught_exception(exc)
    ~~~~~~~~~~~~~~~~~~~~~~~~~~~~~^^^^^
  File "C:\Python\animedia_api\.venv\Lib\site-packages\rest_framework\views.py", line 486, in raise_uncaught_exception
    raise exc
  File "C:\Python\animedia_api\.venv\Lib\site-packages\rest_framework\views.py", line 512, in dispatch
    response = handler(request, *args, **kwargs)
  File "C:\Python\animedia_api\.venv\Lib\site-packages\rest_framework\mixins.py", line 90, in destroy
    instance = self.get_object()
  File "C:\Python\animedia_api\.venv\Lib\site-packages\rest_framework\generics.py", line 103, in get_object
    self.check_object_permissions(self.request, obj)
    ~~~~~~~~~~~~~~~~~~~~~~~~~~~~~^^^^^^^^^^^^^^^^^^^
  File "C:\Python\animedia_api\.venv\Lib\site-packages\rest_framework\views.py", line 351, in check_object_permissions
    if not permission.has_object_permission(request, self, obj):
           ~~~~~~~~~~~~~~~~~~~~~~~~~~~~~~~~^^^^^^^^^^^^^^^^^^^^
  File "C:\Python\animedia_api\core_api\permissions.py", line 17, in has_object_permission
    return obj.owner == request.user
           ^^^^^^^^^
AttributeError: 'Review' object has no attribute 'owner'
Not Found: /api/tradeitems/
Bad Request: /api/auth/register/
Not Found: /api/tradeitems/
Not Found: /api/tradeitems/
Not Found: /api/wishlist/add/7/
Not Found: /api/userprofiles/
Not Found: /api/tradeitems/
Internal Server Error: /api/reviews/4/
Traceback (most recent call last):
  File "C:\Python\animedia_api\.venv\Lib\site-packages\django\core\handlers\exception.py", line 55, in inner
    response = get_response(request)
  File "C:\Python\animedia_api\.venv\Lib\site-packages\django\core\handlers\base.py", line 197, in _get_response
    response = wrapped_callback(request, *callback_args, **callback_kwargs)
  File "C:\Python\animedia_api\.venv\Lib\site-packages\django\views\decorators\csrf.py", line 65, in _view_wrapper
    return view_func(request, *args, **kwargs)
  File "C:\Python\animedia_api\.venv\Lib\site-packages\rest_framework\viewsets.py", line 125, in view
    return self.dispatch(request, *args, **kwargs)
           ~~~~~~~~~~~~~^^^^^^^^^^^^^^^^^^^^^^^^^^
  File "C:\Python\animedia_api\.venv\Lib\site-packages\rest_framework\views.py", line 515, in dispatch
    response = self.handle_exception(exc)
  File "C:\Python\animedia_api\.venv\Lib\site-packages\rest_framework\views.py", line 475, in handle_exception
    self.raise_uncaught_exception(exc)
    ~~~~~~~~~~~~~~~~~~~~~~~~~~~~~^^^^^
  File "C:\Python\animedia_api\.venv\Lib\site-packages\rest_framework\views.py", line 486, in raise_uncaught_exception
    raise exc
  File "C:\Python\animedia_api\.venv\Lib\site-packages\rest_framework\views.py", line 512, in dispatch
    response = handler(request, *args, **kwargs)
  File "C:\Python\animedia_api\.venv\Lib\site-packages\rest_framework\mixins.py", line 90, in destroy
    instance = self.get_object()
  File "C:\Python\animedia_api\.venv\Lib\site-packages\rest_framework\generics.py", line 103, in get_object
    self.check_object_permissions(self.request, obj)
    ~~~~~~~~~~~~~~~~~~~~~~~~~~~~~^^^^^^^^^^^^^^^^^^^
  File "C:\Python\animedia_api\.venv\Lib\site-packages\rest_framework\views.py", line 351, in check_object_permissions
    if not permission.has_object_permission(request, self, obj):
           ~~~~~~~~~~~~~~~~~~~~~~~~~~~~~~~~^^^^^^^^^^^^^^^^^^^^
  File "C:\Python\animedia_api\core_api\permissions.py", line 17, in has_object_permission
    return obj.owner == request.user
           ^^^^^^^^^
AttributeError: 'Review' object has no attribute 'owner'
Not Found: /api/tradeitems/
Watching for file changes with StatReloader
Bad Request: /api/auth/register/
Not Found: /api/tradeitems/
Not Found: /api/tradeitems/
Not Found: /api/wishlist/add/13/
Not Found: /api/userprofiles/
Not Found: /api/tradeitems/
Internal Server Error: /api/reviews/6/
Traceback (most recent call last):
  File "C:\Python\animedia_api\.venv\Lib\site-packages\django\core\handlers\exception.py", line 55, in inner
    response = get_response(request)
  File "C:\Python\animedia_api\.venv\Lib\site-packages\django\core\handlers\base.py", line 197, in _get_response
    response = wrapped_callback(request, *callback_args, **callback_kwargs)
  File "C:\Python\animedia_api\.venv\Lib\site-packages\django\views\decorators\csrf.py", line 65, in _view_wrapper
    return view_func(request, *args, **kwargs)
  File "C:\Python\animedia_api\.venv\Lib\site-packages\rest_framework\viewsets.py", line 125, in view
    return self.dispatch(request, *args, **kwargs)
           ~~~~~~~~~~~~~^^^^^^^^^^^^^^^^^^^^^^^^^^
  File "C:\Python\animedia_api\.venv\Lib\site-packages\rest_framework\views.py", line 515, in dispatch
    response = self.handle_exception(exc)
  File "C:\Python\animedia_api\.venv\Lib\site-packages\rest_framework\views.py", line 475, in handle_exception
    self.raise_uncaught_exception(exc)
    ~~~~~~~~~~~~~~~~~~~~~~~~~~~~~^^^^^
  File "C:\Python\animedia_api\.venv\Lib\site-packages\rest_framework\views.py", line 486, in raise_uncaught_exception
    raise exc
  File "C:\Python\animedia_api\.venv\Lib\site-packages\rest_framework\views.py", line 512, in dispatch
    response = handler(request, *args, **kwargs)
  File "C:\Python\animedia_api\.venv\Lib\site-packages\rest_framework\mixins.py", line 90, in destroy
    instance = self.get_object()
  File "C:\Python\animedia_api\.venv\Lib\site-packages\rest_framework\generics.py", line 103, in get_object
    self.check_object_permissions(self.request, obj)
    ~~~~~~~~~~~~~~~~~~~~~~~~~~~~~^^^^^^^^^^^^^^^^^^^
  File "C:\Python\animedia_api\.venv\Lib\site-packages\rest_framework\views.py", line 351, in check_object_permissions
    if not permission.has_object_permission(request, self, obj):
           ~~~~~~~~~~~~~~~~~~~~~~~~~~~~~~~~^^^^^^^^^^^^^^^^^^^^
  File "C:\Python\animedia_api\core_api\permissions.py", line 17, in has_object_permission
    return obj.owner == request.user
           ^^^^^^^^^
AttributeError: 'Review' object has no attribute 'owner'
Not Found: /api/tradeitems/
Bad Request: /api/auth/register/
Not Found: /api/tradeitems/
Not Found: /api/tradeitems/
Not Found: /api/wishlist/add/19/
Not Found: /api/userprofiles/
Not Found: /api/tradeitems/
Internal Server Error: /api/reviews/8/
Traceback (most recent call last):
  File "C:\Python\animedia_api\.venv\Lib\site-packages\django\core\handlers\exception.py", line 55, in inner
    response = get_response(request)
  File "C:\Python\animedia_api\.venv\Lib\site-packages\django\core\handlers\base.py", line 197, in _get_response
    response = wrapped_callback(request, *callback_args, **callback_kwargs)
  File "C:\Python\animedia_api\.venv\Lib\site-packages\django\views\decorators\csrf.py", line 65, in _view_wrapper
    return view_func(request, *args, **kwargs)
  File "C:\Python\animedia_api\.venv\Lib\site-packages\rest_framework\viewsets.py", line 125, in view
    return self.dispatch(request, *args, **kwargs)
           ~~~~~~~~~~~~~^^^^^^^^^^^^^^^^^^^^^^^^^^
  File "C:\Python\animedia_api\.venv\Lib\site-packages\rest_framework\views.py", line 515, in dispatch
    response = self.handle_exception(exc)
  File "C:\Python\animedia_api\.venv\Lib\site-packages\rest_framework\views.py", line 475, in handle_exception
    self.raise_uncaught_exception(exc)
    ~~~~~~~~~~~~~~~~~~~~~~~~~~~~~^^^^^
  File "C:\Python\animedia_api\.venv\Lib\site-packages\rest_framework\views.py", line 486, in raise_uncaught_exception
    raise exc
  File "C:\Python\animedia_api\.venv\Lib\site-packages\rest_framework\views.py", line 512, in dispatch
    response = handler(request, *args, **kwargs)
  File "C:\Python\animedia_api\.venv\Lib\site-packages\rest_framework\mixins.py", line 90, in destroy
    instance = self.get_object()
  File "C:\Python\animedia_api\.venv\Lib\site-packages\rest_framework\generics.py", line 103, in get_object
    self.check_object_permissions(self.request, obj)
    ~~~~~~~~~~~~~~~~~~~~~~~~~~~~~^^^^^^^^^^^^^^^^^^^
  File "C:\Python\animedia_api\.venv\Lib\site-packages\rest_framework\views.py", line 351, in check_object_permissions
    if not permission.has_object_permission(request, self, obj):
           ~~~~~~~~~~~~~~~~~~~~~~~~~~~~~~~~^^^^^^^^^^^^^^^^^^^^
  File "C:\Python\animedia_api\core_api\permissions.py", line 17, in has_object_permission
    return obj.owner == request.user
           ^^^^^^^^^
AttributeError: 'Review' object has no attribute 'owner'
Not Found: /api/tradeitems/
Internal Server Error: /api/auth/register/
Traceback (most recent call last):
  File "C:\Python\animedia_api\.venv\Lib\site-packages\django\db\backends\utils.py", line 105, in _execute
    return self.cursor.execute(sql, params)
           ~~~~~~~~~~~~~~~~~~~^^^^^^^^^^^^^
psycopg2.errors.UniqueViolation: duplicate key value violates unique constraint "core_api_userprofile_user_id_key"
DETAIL:  Key (user_id)=(69) already exists.


The above exception was the direct cause of the following exception:

Traceback (most recent call last):
  File "C:\Python\animedia_api\.venv\Lib\site-packages\django\core\handlers\exception.py", line 55, in inner
    response = get_response(request)
  File "C:\Python\animedia_api\.venv\Lib\site-packages\django\core\handlers\base.py", line 197, in _get_response
    response = wrapped_callback(request, *callback_args, **callback_kwargs)
  File "C:\Python\animedia_api\.venv\Lib\site-packages\django\views\decorators\csrf.py", line 65, in _view_wrapper
    return view_func(request, *args, **kwargs)
  File "C:\Python\animedia_api\.venv\Lib\site-packages\django\views\generic\base.py", line 104, in view
    return self.dispatch(request, *args, **kwargs)
           ~~~~~~~~~~~~~^^^^^^^^^^^^^^^^^^^^^^^^^^
  File "C:\Python\animedia_api\.venv\Lib\site-packages\rest_framework\views.py", line 515, in dispatch
    response = self.handle_exception(exc)
  File "C:\Python\animedia_api\.venv\Lib\site-packages\rest_framework\views.py", line 475, in handle_exception
    self.raise_uncaught_exception(exc)
    ~~~~~~~~~~~~~~~~~~~~~~~~~~~~~^^^^^
  File "C:\Python\animedia_api\.venv\Lib\site-packages\rest_framework\views.py", line 486, in raise_uncaught_exception
    raise exc
  File "C:\Python\animedia_api\.venv\Lib\site-packages\rest_framework\views.py", line 512, in dispatch
    response = handler(request, *args, **kwargs)
  File "C:\Python\animedia_api\.venv\Lib\site-packages\rest_framework\generics.py", line 194, in post
    return self.create(request, *args, **kwargs)
           ~~~~~~~~~~~^^^^^^^^^^^^^^^^^^^^^^^^^^
  File "C:\Python\animedia_api\.venv\Lib\site-packages\rest_framework\mixins.py", line 19, in create
    self.perform_create(serializer)
    ~~~~~~~~~~~~~~~~~~~^^^^^^^^^^^^
  File "C:\Python\animedia_api\.venv\Lib\site-packages\rest_framework\mixins.py", line 24, in perform_create
    serializer.save()
    ~~~~~~~~~~~~~~~^^
  File "C:\Python\animedia_api\.venv\Lib\site-packages\rest_framework\serializers.py", line 210, in save
    self.instance = self.create(validated_data)
                    ~~~~~~~~~~~^^^^^^^^^^^^^^^^
  File "C:\Python\animedia_api\core_api\serializers.py", line 154, in create
    UserProfile.objects.create(user=user)
    ~~~~~~~~~~~~~~~~~~~~~~~~~~^^^^^^^^^^^
  File "C:\Python\animedia_api\.venv\Lib\site-packages\django\db\models\manager.py", line 87, in manager_method
    return getattr(self.get_queryset(), name)(*args, **kwargs)
           ~~~~~~~~~~~~~~~~~~~~~~~~~~~~~~~~~~^^^^^^^^^^^^^^^^^
  File "C:\Python\animedia_api\.venv\Lib\site-packages\django\db\models\query.py", line 663, in create
    obj.save(force_insert=True, using=self.db)
    ~~~~~~~~^^^^^^^^^^^^^^^^^^^^^^^^^^^^^^^^^^
  File "C:\Python\animedia_api\.venv\Lib\site-packages\django\db\models\base.py", line 902, in save
    self.save_base(
    ~~~~~~~~~~~~~~^
        using=using,
        ^^^^^^^^^^^^
    ...<2 lines>...
        update_fields=update_fields,
        ^^^^^^^^^^^^^^^^^^^^^^^^^^^^
    )
    ^
  File "C:\Python\animedia_api\.venv\Lib\site-packages\django\db\models\base.py", line 1008, in save_base
    updated = self._save_table(
        raw,
    ...<4 lines>...
        update_fields,
    )
  File "C:\Python\animedia_api\.venv\Lib\site-packages\django\db\models\base.py", line 1169, in _save_table
    results = self._do_insert(
        cls._base_manager, using, fields, returning_fields, raw
    )
  File "C:\Python\animedia_api\.venv\Lib\site-packages\django\db\models\base.py", line 1210, in _do_insert
    return manager._insert(
           ~~~~~~~~~~~~~~~^
        [self],
        ^^^^^^^
    ...<3 lines>...
        raw=raw,
        ^^^^^^^^
    )
    ^
  File "C:\Python\animedia_api\.venv\Lib\site-packages\django\db\models\manager.py", line 87, in manager_method
    return getattr(self.get_queryset(), name)(*args, **kwargs)
           ~~~~~~~~~~~~~~~~~~~~~~~~~~~~~~~~~~^^^^^^^^^^^^^^^^^
  File "C:\Python\animedia_api\.venv\Lib\site-packages\django\db\models\query.py", line 1868, in _insert
    return query.get_compiler(using=using).execute_sql(returning_fields)
           ~~~~~~~~~~~~~~~~~~~~~~~~~~~~~~~~~~~~~~~~~~~^^^^^^^^^^^^^^^^^^
  File "C:\Python\animedia_api\.venv\Lib\site-packages\django\db\models\sql\compiler.py", line 1882, in execute_sql
    cursor.execute(sql, params)
    ~~~~~~~~~~~~~~^^^^^^^^^^^^^
  File "C:\Python\animedia_api\.venv\Lib\site-packages\django\db\backends\utils.py", line 79, in execute
    return self._execute_with_wrappers(
           ~~~~~~~~~~~~~~~~~~~~~~~~~~~^
        sql, params, many=False, executor=self._execute
        ^^^^^^^^^^^^^^^^^^^^^^^^^^^^^^^^^^^^^^^^^^^^^^^
    )
    ^
  File "C:\Python\animedia_api\.venv\Lib\site-packages\django\db\backends\utils.py", line 92, in _execute_with_wrappers
    return executor(sql, params, many, context)
  File "C:\Python\animedia_api\.venv\Lib\site-packages\django\db\backends\utils.py", line 100, in _execute
    with self.db.wrap_database_errors:
         ^^^^^^^^^^^^^^^^^^^^^^^^^^^^
  File "C:\Python\animedia_api\.venv\Lib\site-packages\django\db\utils.py", line 91, in __exit__
    raise dj_exc_value.with_traceback(traceback) from exc_value
  File "C:\Python\animedia_api\.venv\Lib\site-packages\django\db\backends\utils.py", line 105, in _execute
    return self.cursor.execute(sql, params)
           ~~~~~~~~~~~~~~~~~~~^^^^^^^^^^^^^
django.db.utils.IntegrityError: duplicate key value violates unique constraint "core_api_userprofile_user_id_key"
DETAIL:  Key (user_id)=(69) already exists.

Not Found: /api/tradeitem/
Not Found: /api/tradeitems/
Unauthorized: /api/wishlist/25/add/
Not Found: /api/userprofiles/
Not Found: /api/tradeitems/
Internal Server Error: /api/reviews/10/
Traceback (most recent call last):
  File "C:\Python\animedia_api\.venv\Lib\site-packages\django\core\handlers\exception.py", line 55, in inner
    response = get_response(request)
  File "C:\Python\animedia_api\.venv\Lib\site-packages\django\core\handlers\base.py", line 197, in _get_response
    response = wrapped_callback(request, *callback_args, **callback_kwargs)
  File "C:\Python\animedia_api\.venv\Lib\site-packages\django\views\decorators\csrf.py", line 65, in _view_wrapper
    return view_func(request, *args, **kwargs)
  File "C:\Python\animedia_api\.venv\Lib\site-packages\rest_framework\viewsets.py", line 125, in view
    return self.dispatch(request, *args, **kwargs)
           ~~~~~~~~~~~~~^^^^^^^^^^^^^^^^^^^^^^^^^^
  File "C:\Python\animedia_api\.venv\Lib\site-packages\rest_framework\views.py", line 515, in dispatch
    response = self.handle_exception(exc)
  File "C:\Python\animedia_api\.venv\Lib\site-packages\rest_framework\views.py", line 475, in handle_exception
    self.raise_uncaught_exception(exc)
    ~~~~~~~~~~~~~~~~~~~~~~~~~~~~~^^^^^
  File "C:\Python\animedia_api\.venv\Lib\site-packages\rest_framework\views.py", line 486, in raise_uncaught_exception
    raise exc
  File "C:\Python\animedia_api\.venv\Lib\site-packages\rest_framework\views.py", line 512, in dispatch
    response = handler(request, *args, **kwargs)
  File "C:\Python\animedia_api\.venv\Lib\site-packages\rest_framework\mixins.py", line 90, in destroy
    instance = self.get_object()
  File "C:\Python\animedia_api\.venv\Lib\site-packages\rest_framework\generics.py", line 103, in get_object
    self.check_object_permissions(self.request, obj)
    ~~~~~~~~~~~~~~~~~~~~~~~~~~~~~^^^^^^^^^^^^^^^^^^^
  File "C:\Python\animedia_api\.venv\Lib\site-packages\rest_framework\views.py", line 351, in check_object_permissions
    if not permission.has_object_permission(request, self, obj):
           ~~~~~~~~~~~~~~~~~~~~~~~~~~~~~~~~^^^^^^^^^^^^^^^^^^^^
  File "C:\Python\animedia_api\core_api\permissions.py", line 17, in has_object_permission
    return obj.owner == request.user
           ^^^^^^^^^
AttributeError: 'Review' object has no attribute 'owner'
Not Found: /api/tradeitems/
C:\Python\animedia_api\core_api\serializers.py changed, reloading.
Watching for file changes with StatReloader
Not Found: /api/token/
Not Found: /api/wishlist/add/31/
Bad Request: /api/items/
Unauthorized: /api/wishlist/32/add/
Not Found: /api/userprofiles/
Not Found: /api/tradeitems/
Internal Server Error: /api/reviews/12/
Traceback (most recent call last):
  File "C:\Python\animedia_api\.venv\Lib\site-packages\django\core\handlers\exception.py", line 55, in inner
    response = get_response(request)
  File "C:\Python\animedia_api\.venv\Lib\site-packages\django\core\handlers\base.py", line 197, in _get_response
    response = wrapped_callback(request, *callback_args, **callback_kwargs)
  File "C:\Python\animedia_api\.venv\Lib\site-packages\django\views\decorators\csrf.py", line 65, in _view_wrapper
    return view_func(request, *args, **kwargs)
  File "C:\Python\animedia_api\.venv\Lib\site-packages\rest_framework\viewsets.py", line 125, in view
    return self.dispatch(request, *args, **kwargs)
           ~~~~~~~~~~~~~^^^^^^^^^^^^^^^^^^^^^^^^^^
  File "C:\Python\animedia_api\.venv\Lib\site-packages\rest_framework\views.py", line 515, in dispatch
    response = self.handle_exception(exc)
  File "C:\Python\animedia_api\.venv\Lib\site-packages\rest_framework\views.py", line 475, in handle_exception
    self.raise_uncaught_exception(exc)
    ~~~~~~~~~~~~~~~~~~~~~~~~~~~~~^^^^^
  File "C:\Python\animedia_api\.venv\Lib\site-packages\rest_framework\views.py", line 486, in raise_uncaught_exception
    raise exc
  File "C:\Python\animedia_api\.venv\Lib\site-packages\rest_framework\views.py", line 512, in dispatch
    response = handler(request, *args, **kwargs)
  File "C:\Python\animedia_api\.venv\Lib\site-packages\rest_framework\mixins.py", line 90, in destroy
    instance = self.get_object()
  File "C:\Python\animedia_api\.venv\Lib\site-packages\rest_framework\generics.py", line 103, in get_object
    self.check_object_permissions(self.request, obj)
    ~~~~~~~~~~~~~~~~~~~~~~~~~~~~~^^^^^^^^^^^^^^^^^^^
  File "C:\Python\animedia_api\.venv\Lib\site-packages\rest_framework\views.py", line 351, in check_object_permissions
    if not permission.has_object_permission(request, self, obj):
           ~~~~~~~~~~~~~~~~~~~~~~~~~~~~~~~~^^^^^^^^^^^^^^^^^^^^
  File "C:\Python\animedia_api\core_api\permissions.py", line 17, in has_object_permission
    return obj.owner == request.user
           ^^^^^^^^^
AttributeError: 'Review' object has no attribute 'owner'
Not Found: /api/tradeitems/
C:\Python\animedia_api\core_api\permissions.py changed, reloading.
Watching for file changes with StatReloader
Not Found: /api/token/
Not Found: /api/wishlist/add/38/
Bad Request: /api/items/
Unauthorized: /api/wishlist/39/add/
Not Found: /api/userprofiles/
Not Found: /api/tradeitems/
Forbidden: /api/reviews/14/
Bad Request: /api/items/
Unauthorized: /api/wishlist/46/add/
Internal Server Error: /api/profiles/
Traceback (most recent call last):
  File "C:\Python\animedia_api\.venv\Lib\site-packages\django\core\handlers\exception.py", line 55, in inner
    response = get_response(request)
  File "C:\Python\animedia_api\.venv\Lib\site-packages\django\core\handlers\base.py", line 197, in _get_response
    response = wrapped_callback(request, *callback_args, **callback_kwargs)
  File "C:\Python\animedia_api\.venv\Lib\site-packages\django\views\decorators\csrf.py", line 65, in _view_wrapper
    return view_func(request, *args, **kwargs)
  File "C:\Python\animedia_api\.venv\Lib\site-packages\django\views\generic\base.py", line 104, in view
    return self.dispatch(request, *args, **kwargs)
           ~~~~~~~~~~~~~^^^^^^^^^^^^^^^^^^^^^^^^^^
  File "C:\Python\animedia_api\.venv\Lib\site-packages\rest_framework\views.py", line 515, in dispatch
    response = self.handle_exception(exc)
  File "C:\Python\animedia_api\.venv\Lib\site-packages\rest_framework\views.py", line 475, in handle_exception
    self.raise_uncaught_exception(exc)
    ~~~~~~~~~~~~~~~~~~~~~~~~~~~~~^^^^^
  File "C:\Python\animedia_api\.venv\Lib\site-packages\rest_framework\views.py", line 486, in raise_uncaught_exception
    raise exc
  File "C:\Python\animedia_api\.venv\Lib\site-packages\rest_framework\views.py", line 512, in dispatch
    response = handler(request, *args, **kwargs)
  File "C:\Python\animedia_api\.venv\Lib\site-packages\rest_framework\generics.py", line 203, in get
    return self.list(request, *args, **kwargs)
           ~~~~~~~~~^^^^^^^^^^^^^^^^^^^^^^^^^^
  File "C:\Python\animedia_api\.venv\Lib\site-packages\rest_framework\mixins.py", line 40, in list
    page = self.paginate_queryset(queryset)
  File "C:\Python\animedia_api\.venv\Lib\site-packages\rest_framework\generics.py", line 175, in paginate_queryset
    return self.paginator.paginate_queryset(queryset, self.request, view=self)
           ~~~~~~~~~~~~~~~~~~~~~~~~~~~~~~~~^^^^^^^^^^^^^^^^^^^^^^^^^^^^^^^^^^^
  File "C:\Python\animedia_api\.venv\Lib\site-packages\rest_framework\pagination.py", line 630, in paginate_queryset
    queryset = queryset.order_by(*self.ordering)
  File "C:\Python\animedia_api\.venv\Lib\site-packages\django\db\models\query.py", line 1722, in order_by
    obj.query.add_ordering(*field_names)
    ~~~~~~~~~~~~~~~~~~~~~~^^^^^^^^^^^^^^
  File "C:\Python\animedia_api\.venv\Lib\site-packages\django\db\models\sql\query.py", line 2291, in add_ordering
    self.names_to_path(item.split(LOOKUP_SEP), self.model._meta)
    ~~~~~~~~~~~~~~~~~~^^^^^^^^^^^^^^^^^^^^^^^^^^^^^^^^^^^^^^^^^^
  File "C:\Python\animedia_api\.venv\Lib\site-packages\django\db\models\sql\query.py", line 1805, in names_to_path
    raise FieldError(
    ...<2 lines>...
    )
django.core.exceptions.FieldError: Cannot resolve keyword 'created' into field. Choices are: avatar, bio, created_at, favorite_genres, id, updated_at, user, user_id
Internal Server Error: /api/items/50/
Traceback (most recent call last):
  File "C:\Python\animedia_api\.venv\Lib\site-packages\django\core\handlers\exception.py", line 55, in inner
    response = get_response(request)
  File "C:\Python\animedia_api\.venv\Lib\site-packages\django\core\handlers\base.py", line 197, in _get_response
    response = wrapped_callback(request, *callback_args, **callback_kwargs)
  File "C:\Python\animedia_api\.venv\Lib\site-packages\django\views\decorators\csrf.py", line 65, in _view_wrapper
    return view_func(request, *args, **kwargs)
  File "C:\Python\animedia_api\.venv\Lib\site-packages\rest_framework\viewsets.py", line 125, in view
    return self.dispatch(request, *args, **kwargs)
           ~~~~~~~~~~~~~^^^^^^^^^^^^^^^^^^^^^^^^^^
  File "C:\Python\animedia_api\.venv\Lib\site-packages\rest_framework\views.py", line 515, in dispatch
    response = self.handle_exception(exc)
  File "C:\Python\animedia_api\.venv\Lib\site-packages\rest_framework\views.py", line 475, in handle_exception
    self.raise_uncaught_exception(exc)
    ~~~~~~~~~~~~~~~~~~~~~~~~~~~~~^^^^^
  File "C:\Python\animedia_api\.venv\Lib\site-packages\rest_framework\views.py", line 486, in raise_uncaught_exception
    raise exc
  File "C:\Python\animedia_api\.venv\Lib\site-packages\rest_framework\views.py", line 512, in dispatch
    response = handler(request, *args, **kwargs)
  File "C:\Python\animedia_api\.venv\Lib\site-packages\rest_framework\mixins.py", line 82, in partial_update
    return self.update(request, *args, **kwargs)
           ~~~~~~~~~~~^^^^^^^^^^^^^^^^^^^^^^^^^^
  File "C:\Python\animedia_api\.venv\Lib\site-packages\rest_framework\mixins.py", line 65, in update
    instance = self.get_object()
  File "C:\Python\animedia_api\.venv\Lib\site-packages\rest_framework\generics.py", line 103, in get_object
    self.check_object_permissions(self.request, obj)
    ~~~~~~~~~~~~~~~~~~~~~~~~~~~~~^^^^^^^^^^^^^^^^^^^
  File "C:\Python\animedia_api\.venv\Lib\site-packages\rest_framework\views.py", line 351, in check_object_permissions
    if not permission.has_object_permission(request, self, obj):
           ~~~~~~~~~~~~~~~~~~~~~~~~~~~~~~~~^^^^^^^^^^^^^^^^^^^^
  File "C:\Python\animedia_api\core_api\permissions.py", line 17, in has_object_permission
    return obj.reviewer == request.user
           ^^^^^^^^^^^^
AttributeError: 'TradeItem' object has no attribute 'reviewer'
Forbidden: /api/reviews/16/
C:\Python\animedia_api\core_api\views.py changed, reloading.
Watching for file changes with StatReloader
C:\Python\animedia_api\core_api\permissions.py changed, reloading.
Watching for file changes with StatReloader
Bad Request: /api/items/
Unauthorized: /api/wishlist/54/add/
Internal Server Error: /api/reviews/18/
Traceback (most recent call last):
  File "C:\Python\animedia_api\.venv\Lib\site-packages\django\core\handlers\exception.py", line 55, in inner
    response = get_response(request)
  File "C:\Python\animedia_api\.venv\Lib\site-packages\django\core\handlers\base.py", line 197, in _get_response
    response = wrapped_callback(request, *callback_args, **callback_kwargs)
  File "C:\Python\animedia_api\.venv\Lib\site-packages\django\views\decorators\csrf.py", line 65, in _view_wrapper
    return view_func(request, *args, **kwargs)
  File "C:\Python\animedia_api\.venv\Lib\site-packages\rest_framework\viewsets.py", line 125, in view
    return self.dispatch(request, *args, **kwargs)
           ~~~~~~~~~~~~~^^^^^^^^^^^^^^^^^^^^^^^^^^
  File "C:\Python\animedia_api\.venv\Lib\site-packages\rest_framework\views.py", line 515, in dispatch
    response = self.handle_exception(exc)
  File "C:\Python\animedia_api\.venv\Lib\site-packages\rest_framework\views.py", line 475, in handle_exception
    self.raise_uncaught_exception(exc)
    ~~~~~~~~~~~~~~~~~~~~~~~~~~~~~^^^^^
  File "C:\Python\animedia_api\.venv\Lib\site-packages\rest_framework\views.py", line 486, in raise_uncaught_exception
    raise exc
  File "C:\Python\animedia_api\.venv\Lib\site-packages\rest_framework\views.py", line 512, in dispatch
    response = handler(request, *args, **kwargs)
  File "C:\Python\animedia_api\.venv\Lib\site-packages\rest_framework\mixins.py", line 90, in destroy
    instance = self.get_object()
  File "C:\Python\animedia_api\.venv\Lib\site-packages\rest_framework\generics.py", line 103, in get_object
    self.check_object_permissions(self.request, obj)
    ~~~~~~~~~~~~~~~~~~~~~~~~~~~~~^^^^^^^^^^^^^^^^^^^
  File "C:\Python\animedia_api\.venv\Lib\site-packages\rest_framework\views.py", line 351, in check_object_permissions
    if not permission.has_object_permission(request, self, obj):
           ~~~~~~~~~~~~~~~~~~~~~~~~~~~~~~~~^^^^^^^^^^^^^^^^^^^^
  File "C:\Python\animedia_api\core_api\permissions.py", line 17, in has_object_permission
    return obj.owner == request.user
           ^^^^^^^^^
AttributeError: 'Review' object has no attribute 'owner'
C:\Python\animedia_api\core_api\permissions.py changed, reloading.
Watching for file changes with StatReloader
Bad Request: /api/items/
Unauthorized: /api/wishlist/62/add/
Forbidden: /api/reviews/20/
Bad Request: /api/items/
Unauthorized: /api/wishlist/70/add/
Forbidden: /api/reviews/22/
Bad Request: /api/items/
Unauthorized: /api/wishlist/78/add/
Forbidden: /api/reviews/24/
Unauthorized: /api/wishlist/87/add/
Forbidden: /api/reviews/26/
Unauthorized: /api/wishlist/96/add/
Forbidden: /api/reviews/28/
Unauthorized: /api/wishlist/106/add/
Forbidden: /api/reviews/30/
Unauthorized: /api/wishlist/116/add/
Forbidden: /api/reviews/32/
Unauthorized: /api/wishlist/126/add/
Unauthorized: /api/profiles/
Forbidden: /api/reviews/34/
Unauthorized: /api/wishlist/136/add/
Unauthorized: /api/profiles/
Forbidden: /api/reviews/36/
Unauthorized: /api/wishlist/146/add/
Unauthorized: /api/profiles/
Forbidden: /api/reviews/38/
Unauthorized: /api/wishlist/156/add/
Unauthorized: /api/profiles/
Forbidden: /api/reviews/40/
Unauthorized: /api/wishlist/166/add/
Unauthorized: /api/profiles/
Forbidden: /api/reviews/42/
Unauthorized: /api/wishlist/176/add/
Unauthorized: /api/profiles/
Forbidden: /api/reviews/44/
